Workbook

Sheet Backlog
A1: Story ID | B1: Epic / Module | C1: Type | D1: User Story (As a ... I want ... so that ...) | E1: Acceptance Criteria | F1: Priority | G1: Points | H1: Sprint | I1: Status | J1: Owner | K1: Depends On | L1: Risk | M1: Tasks | N1: Est (h) | O1: Actual (h) | P1: Remain (h) | Q1: Progress | R1: Demo in review | S1: Note
A2: US-01 | B2: Auth | D2: As a visitor, I want to register a learner or instructor account so that I can access the platform. | E2: Email + password validated; a verification email is sent; a user can hold both learner and instructor roles (FR-AUTH-03). | F2: Must | G2: 8 | H2: Sprint 1 | I2: done | J2: DuongNT182 | R2: Yes
A3: US-02 | B3: Auth | D3: As a registered user, I want to log in and get role-based access so that I can use the features for my role. | E3: Correct credentials return a session/JWT; role drives authorization; account locks 30 min after 5 wrong tries. | F3: Must | G3: 8 | H3: Sprint 3 | I3: done | J3: DuongNT182 | K3: US-01 | R3: Yes
A4: US-03 | B4: Auth | D4: As a user, I want to sign in with Google/Facebook so that I do not manage another password. | E4: OAuth login creates or links an account; a returning OAuth user lands logged in. | F4: Should | G4: 5 | H4: Sprint 4 | I4: todo | J4: DuongNT182 | K4: US-01 | R4: Yes
A5: US-04 | B5: Auth | D5: As a signed-in user, I want to view and edit my profile so that my account details stay current. | E5: View profile; edit name/avatar; change password with a current-password check. | F5: Should | G5: 5 | H5: Sprint 2 | I5: done | J5: DuongNT182 | K5: US-02 | R5: Yes
A6: US-05 | B6: Course Authoring | D6: As an instructor, I want to create and edit a course and set its price so that I can publish it for sale. | E6: Course CRUD with title/description/thumbnail/price; draft vs published state; only the owner can edit. | F6: Must | G6: 8 | H6: Sprint 2 | I6: done | J6: TienPQ9 | K6: US-01 | R6: Yes
A7: US-06 | B7: Course Authoring | D7: As an instructor, I want to add and edit multi-format lessons (video, text, file) so that my course has real content. | E7: Lessons ordered within sections; video stored by storage_key not a public URL; add/edit/delete lesson. | F7: Must | G7: 13 | H7: Sprint 2 | I7: done | J7: TienPQ9 | K7: US-05 | R7: Yes
A8: US-07 | B8: Quiz | D8: As an instructor, I want to create a quiz for a lesson so that learners can test themselves. | E8: Quiz with questions/options and a correct answer; attached to a lesson. | F8: Should | G8: 5 | H8: Sprint 3 | I8: done | J8: DuongNT182 | K8: US-06 | R8: Yes
A9: US-08 | B9: Instructor | D9: As an instructor, I want to manage the courses I have published so that I can keep them up to date. | E9: List own courses with status; unpublish/republish; see enrollment count. | F9: Should | G9: 3 | H9: Sprint 2 | I9: done | J9: DuongNT182 | K9: US-05 | R9: Yes
A10: US-09 | B10: Instructor | D10: As an instructor, I want to see my revenue so that I know how my courses perform. | E10: Revenue per course and total, from completed (paid) orders only. | F10: Could | G10: 5 | H10: Sprint 4 | I10: done | J10: TienPQ9 | K10: US-14 | R10: Yes
A11: US-10 | B11: Discovery | D11: As a learner, I want to search and filter courses so that I can find what I want. | E11: Search by keyword; filter by category/price; paginated results. | F11: Should | G11: 5 | H11: Sprint 2 | I11: done | J11: TungNT188 | K11: US-05 | R11: Yes
A12: US-11 | B12: Discovery | D12: As a learner, I want to view a course landing page and preview lesson (if have) so that I can decide before buying. | E12: Shows description, curriculum, price and rating; free-preview lessons if any. | F12: Must | G12: 3 | H12: Sprint 2 | I12: done | J12: TungNT188 | K12: US-05 | R12: Yes
A13: US-13 | B13: Payment | D13: As a learner, I want to create an order and be redirected to the payment gateway so that I can pay for a course. | E13: Order created with a unique order_code; redirect to MoMo/VNPay; order stays pending until IPN confirms. | F13: Must | G13: 8 | H13: Sprint 3 | I13: done | J13: TungNT188 | K13: US-11 | R13: Yes
A14: US-14 | B14: Payment | D14: As a learner,I want the system to automatically grant me course access right after my payment is successful,So that I can start learning immediately without waiting for manual approval. | E14: Server-to-server IPN verified; duplicate IPN is idempotent (FR-PAY-03); enrollment created on success; browser redirect is not trusted for confirmation. | F14: Must | G14: 8 | H14: Sprint 3 | I14: done | J14: TungNT188 | K14: US-13 | R14: Yes
... A22: US-22 | B22: AI | D22: As a learner, I want similar-course suggestions so that I discover relevant courses. | E22: Recommendations from the learner profile/history; shown on course and home pages. | F22: Should | G22: 8 | H22: Sprint 4 | I22: done | J22: DuongNT182 | K22: US-11 | R22: Yes
A23: US-23 | B23: AI | D23: As an instructor, I want AI to generate draft quiz questions from uploaded course materials so that I can prepare quizzes more quickly. | E23: The system generates draft quiz questions based on the document, the instructor can review and edit the questions before using them. | F23: Should | G23: 5 | H23: Sprint 4 | I23: done | J23: TienPQ9 | K23: US-05
A24: US-24 | B24: AI | D24: As an instructor, I want AI to suggest learning outcomes and create a curriculum draft so that I can plan a course more efficiently. | E24: The instructor can request suggested learning outcomes for a course, the system generates a curriculum draft based on the available course information. | F24: Should | G24: 5 | H24: Sprint 4 | I24: done | J24: TienPQ9 | K24: US-05
M27: =IF($A27="","",COUNTIF(WBS!$A:$A,$A27)) | N27: =IF($A27="","",SUMIF(WBS!$A:$A,$A27,WBS!$E:$E)) | O27: =IF($A27="","",SUMIF(WBS!$A:$A,$A27,WBS!$L:$L)) | P27: =IF($A27="","",SUMIF(WBS!$A:$A,$A27,WBS!$M:$M)) | Q27: =IF($A27="","",IFERROR(SUMIFS(WBS!$E:$E,WBS!$A:$A,$A27,WBS!$F:$F,"done")/$N27,0))
M28: =IF($A28="","",COUNTIF(WBS!$A:$A,$A28)) | N28: =IF($A28="","",SUMIF(WBS!$A:$A,$A28,WBS!$E:$E)) | O28: =IF($A28="","",SUMIF(WBS!$A:$A,$A28,WBS!$L:$L)) | P28: =IF($A28="","",SUMIF(WBS!$A:$A,$A28,WBS!$M:$M)) | Q28: =IF($A28="","",IFERROR(SUMIFS(WBS!$E:$E,WBS!$A:$A,$A28,WBS!$F:$F,"done")/$N28,0))
M29: =IF($A29="","",COUNTIF(WBS!$A:$A,$A29)) | N29: =IF($A29="","",SUMIF(WBS!$A:$A,$A29,WBS!$E:$E)) | O29: =IF($A29="","",SUMIF(WBS!$A:$A,$A29,WBS!$L:$L)) | P29: =IF($A29="","",SUMIF(WBS!$A:$A,$A29,WBS!$M:$M)) | Q29: =IF($A29="","",IFERROR(SUMIFS(WBS!$E:$E,WBS!$A:$A,$A29,WBS!$F:$F,"done")/$N29,0))
M30: =IF($A30="","",COUNTIF(WBS!$A:$A,$A30)) | N30: =IF($A30="","",SUMIF(WBS!$A:$A,$A30,WBS!$E:$E)) | O30: =IF($A30="","",SUMIF(WBS!$A:$A,$A30,WBS!$L:$L)) | P30: =IF($A30="","",SUMIF(WBS!$A:$A,$A30,WBS!$M:$M)) | Q30: =IF($A30="","",IFERROR(SUMIFS(WBS!$E:$E,WBS!$A:$A,$A30,WBS!$F:$F,"done")/$N30,0))
M31: =IF($A31="","",COUNTIF(WBS!$A:$A,$A31)) | N31: =IF($A31="","",SUMIF(WBS!$A:$A,$A31,WBS!$E:$E)) | O31: =IF($A31="","",SUMIF(WBS!$A:$A,$A31,WBS!$L:$L)) | P31: =IF($A31="","",SUMIF(WBS!$A:$A,$A31,WBS!$M:$M)) | Q31: =IF($A31="","",IFERROR(SUMIFS(WBS!$E:$E,WBS!$A:$A,$A31,WBS!$F:$F,"done")/$N31,0))
M32: =IF($A32="","",COUNTIF(WBS!$A:$A,$A32)) | N32: =IF($A32="","",SUMIF(WBS!$A:$A,$A32,WBS!$E:$E)) | O32: =IF($A32="","",SUMIF(WBS!$A:$A,$A32,WBS!$L:$L)) | P32: =IF($A32="","",SUMIF(WBS!$A:$A,$A32,WBS!$M:$M)) | Q32: =IF($A32="","",IFERROR(SUMIFS(WBS!$E:$E,WBS!$A:$A,$A32,WBS!$F:$F,"done")/$N32,0))
M33: =IF($A33="","",COUNTIF(WBS!$A:$A,$A33)) | N33: =IF($A33="","",SUMIF(WBS!$A:$A,$A33,WBS!$E:$E)) | O33: =IF($A33="","",SUMIF(WBS!$A:$A,$A33,WBS!$L:$L)) | P33: =IF($A33="","",SUMIF(WBS!$A:$A,$A33,WBS!$M:$M)) | Q33: =IF($A33="","",IFERROR(SUMIFS(WBS!$E:$E,WBS!$A:$A,$A33,WBS!$F:$F,"done")/$N33,0))
M34: =IF($A34="","",COUNTIF(WBS!$A:$A,$A34)) | N34: =IF($A34="","",SUMIF(WBS!$A:$A,$A34,WBS!$E:$E)) | O34: =IF($A34="","",SUMIF(WBS!$A:$A,$A34,WBS!$L:$L)) | P34: =IF($A34="","",SUMIF(WBS!$A:$A,$A34,WBS!$M:$M)) | Q34: =IF($A34="","",IFERROR(SUMIFS(WBS!$E:$E,WBS!$A:$A,$A34,WBS!$F:$F,"done")/$N34,0))
M35: =IF($A35="","",COUNTIF(WBS!$A:$A,$A35)) | N35: =IF($A35="","",SUMIF(WBS!$A:$A,$A35,WBS!$E:$E)) | O35: =IF($A35="","",SUMIF(WBS!$A:$A,$A35,WBS!$L:$L)) | P35: =IF($A35="","",SUMIF(WBS!$A:$A,$A35,WBS!$M:$M)) | Q35: =IF($A35="","",IFERROR(SUMIFS(WBS!$E:$E,WBS!$A:$A,$A35,WBS!$F:$F,"done")/$N35,0))
M36: =IF($A36="","",COUNTIF(WBS!$A:$A,$A36)) | N36: =IF($A36="","",SUMIF(WBS!$A:$A,$A36,WBS!$E:$E)) | O36: =IF($A36="","",SUMIF(WBS!$A:$A,$A36,WBS!$L:$L)) | P36: =IF($A36="","",SUMIF(WBS!$A:$A,$A36,WBS!$M:$M)) | Q36: =IF($A36="","",IFERROR(SUMIFS(WBS!$E:$E,WBS!$A:$A,$A36,WBS!$F:$F,"done")/$N36,0))
M37: =IF($A37="","",COUNTIF(WBS!$A:$A,$A37)) | N37: =IF($A37="","",SUMIF(WBS!$A:$A,$A37,WBS!$E:$E)) | O37: =IF($A37="","",SUMIF(WBS!$A:$A,$A37,WBS!$L:$L)) | P37: =IF($A37="","",SUMIF(WBS!$A:$A,$A37,WBS!$M:$M)) | Q37: =IF($A37="","",IFERROR(SUMIFS(WBS!$E:$E,WBS!$A:$A,$A37,WBS!$F:$F,"done")/$N37,0))
M38: =IF($A38="","",COUNTIF(WBS!$A:$A,$A38)) | N38: =IF($A38="","",SUMIF(WBS!$A:$A,$A38,WBS!$E:$E)) | O38: =IF($A38="","",SUMIF(WBS!$A:$A,$A38,WBS!$L:$L)) | P38: =IF($A38="","",SUMIF(WBS!$A:$A,$A38,WBS!$M:$M)) | Q38: =IF($A38="","",IFERROR(SUMIFS(WBS!$E:$E,WBS!$A:$A,$A38,WBS!$F:$F,"done")/$N38,0))
... M59: =IF($A59="","",COUNTIF(WBS!$A:$A,$A59)) | N59: =IF($A59="","",SUMIF(WBS!$A:$A,$A59,WBS!$E:$E)) | O59: =IF($A59="","",SUMIF(WBS!$A:$A,$A59,WBS!$L:$L)) | P59: =IF($A59="","",SUMIF(WBS!$A:$A,$A59,WBS!$M:$M)) | Q59: =IF($A59="","",IFERROR(SUMIFS(WBS!$E:$E,WBS!$A:$A,$A59,WBS!$F:$F,"done")/$N59,0))
A61: Blue text = a formula rolled up from WBS on Story ID - do not type over it. Rows 2 to 5 are worked examples - delete them before you submit.

Sheet WBS
A1: Story ID | B1: Task ID | C1: Task | D1: Assignee | E1: Estimate (h) | F1: Status | G1: Note | H1: Sprint | I1: Task Type | J1: Planned Start | K1: Planned End | L1: Actual (h) | M1: Remain (h) | N1: Blocked By | O1: Reviewer | P1: Done Date | Q1: Evidence (PR / commit)
B2: T-001 | C2: Complete Project Proposal | D2: TienPQ9 | F2: done | H2: Sprint 1
B3: T-002 | C3: Initiate Backlog And WBS | D3: TienPQ9 | F3: done | H3: Sprint 1
B4: T-003 | C4: Initiate Database 01 | D4: TungNT188 | F4: done | H4: Sprint 1
B5: T-004 | C5: Initiate SRS v 01 | D5: TienPQ9 | F5: done | H5: Sprint 1
B6: T-005 | C6: Initiate HLD & LLD v01 | D6: TungNT188 | F6: done | H6: Sprint 1
B7: T-006 | C7: Project skeleton + users schema (V1) | D7: DuongNT182 | F7: done | H7: Sprint 1
A8: US-01 | B8: T-012 | C8: Registration: API + email verification | D8: DuongNT182 | F8: done | H8: Sprint 1
A9: US-01 | B9: T-013 | C9: Register screen (learner / instructor) | D9: DuongNT182 | F9: done | H9: Sprint 1
A10: US-04 | B10: T-041 | C10: Profile API + change password | D10: DuongNT182 | F10: done | H10: Sprint 2
A11: US-04 | B11: T-042 | C11: Profile view / edit screen + avatar, information,.. ( especially instructor need setup profile before create course) | D11: DuongNT182 | F11: done | H11: Sprint 2
A12: US-08 | B12: T-081 | C12: API: list instructor's own courses with status and enrollment count | D12: TienPQ9 | F12: done | H12: Sprint 2
A13: US-08 | B13: T-082 | C13: API: unpublish / republish a course | D13: TienPQ9 | F13: done | H13: Sprint 2
A14: US-08 | B14: T-083 | C14: Instructor "My Courses" screen | D14: TienPQ9 | F14: done | H14: Sprint 2
A15: US-05 | B15: T-051 | C15: Course CRUD API: title, description, thumbnail, price | D15: TienPQ9 | F15: done | H15: Sprint 2
A16: US-05 | B16: T-052 | C16: Create / edit course screen | D16: TienPQ9 | F16: done | H16: Sprint 2
A17: US-05 | B17: T-053 | C17: Draft / published state and owner-only edit check | D17: TienPQ9 | F17: done | H17: Sprint 2
A18: US-06 | B18: T-061 | C18: Create course with content, section, lesson | D18: TienPQ9 | F18: done | H18: Sprint 2
A19: US-06 | B19: T-062 | C19: Lesson CRUD API (video / text / file), stores storage_key | D19: TienPQ9 | F19: done | H19: Sprint 2 | M19: =IF($C19="","",IF($F19="done",0,MAX($E19-$L19,0))) -> 0
A20: US-06 | B20: T-063 | C20: Course content screen: section–lesson tree, drag to reorder | D20: TienPQ9 | F20: done | H20: Sprint 2 | M20: =IF($C20="","",IF($F20="done",0,MAX($E20-$L20,0))) -> 0
A21: US-10 | B21: T-101 | C21: Search API: keyword, category and price filters, pagination | D21: TungNT188 | F21: done | H21: Sprint 2 | M21: =IF($C21="","",IF($F21="done",0,MAX($E21-$L21,0))) -> 0
A22: US-10 | B22: T-102 | C22: Course list screen with filter bar | D22: TungNT188 | F22: done | H22: Sprint 2 | M22: =IF($C22="","",IF($F22="done",0,MAX($E22-$L22,0))) -> 0
A23: US-11 | B23: T-111 | C23: Course detail API: description, curriculum, price, rating | D23: TungNT188 | F23: done | H23: Sprint 2 | M23: =IF($C23="","",IF($F23="done",0,MAX($E23-$L23,0))) -> 0
A24: US-11 | B24: T-112 | C24: Mark lessons as free preview and serve preview content | D24: TungNT188 | F24: done | H24: Sprint 2 | M24: =IF($C24="","",IF($F24="done",0,MAX($E24-$L24,0))) -> 0
A25: US-11 | B25: T-113 | C25: Course landing page screen | D25: TungNT188 | F25: done | H25: Sprint 2 | M25: =IF($C25="","",IF($F25="done",0,MAX($E25-$L25,0))) -> 0
A26: US-16 | B26: T-161 | C26: API: course curriculum for enrolled learner (sections, lessons, current lesson) | D26: TungNT188 | F26: done | H26: Sprint 2
A27: US-16 | B27: T-162 | C27: Player screen layout: video area plus section–lesson sidebar | D27: TungNT188 | F27: done | H27: Sprint 2
A28: US-19 | B28: T-191 | C28: API: list active enrollments with course info and resume target | D28: TungNT188 | F28: done | H28: Sprint 2
A29: US-19 | B29: T-192 | C29: "My Courses" screen | D29: TungNT188 | F29: done | H29: Sprint 2
A30: US-02 | B30: T-021 | C30: Login + session/JWT + role-based authorization + lockout | D30: DuongNT182 | F30: done | H30: Sprint 2
A31: US-02 | B31: T-022 | C31: Login screen + error messages | D31: DuongNT182 | F31: done | H31: Sprint 2
A32: US-07 | B32: T-071 | C32: Migration and CRUD API for quiz, questions, options, correct answer | D32: DuongNT182 | F32: done | H32: Sprint 3 | M32: =IF($C32="","",IF($F32="done",0,MAX($E32-$L32,0))) -> 0
A33: US-07 | B33: T-072 | C33: Instructor quiz builder screen | D33: DuongNT182 | F33: done | H33: Sprint 3 | M33: =IF($C33="","",IF($F33="done",0,MAX($E33-$L33,0))) -> 0
A34: US-20 | B34: T-201 | C34: Quiz attempt API: submit answers, auto-grade, persist attempt | D34: DuongNT182 | F34: done | H34: Sprint 3 | M34: =IF($C34="","",IF($F34="done",0,MAX($E34-$L34,0))) -> 0
A35: US-20 | B35: T-202 | C35: Quiz-taking screen with score and per-question result | D35: DuongNT182 | F35: done | H35: Sprint 3 | M35: =IF($C35="","",IF($F35="done",0,MAX($E35-$L35,0))) -> 0
A36: US-13 | B36: T-131 | C36: Build signed payment request and redirect to payos | D36: TungNT188 | F36: done | H36: Sprint 3 | M36: =IF($C36="","",IF($F36="done",0,MAX($E36-$L36,0))) -> 0
A37: US-13 | B37: T-132 | C37: Buy button and payment-result screen reading order status | D37: TungNT188 | F37: done | H37: Sprint 3 | M37: =IF($C37="","",IF($F37="done",0,MAX($E37-$L37,0))) -> 0
A38: US-14 | B38: T-141 | C38: IPN endpoint: verify gateway signature, update order status | D38: TungNT188 | F38: done | H38: Sprint 3 | M38: =IF($C38="","",IF($F38="done",0,MAX($E38-$L38,0))) -> 0
A39: US-14 | B39: T-142 | C39: Create enrollment on successful payment | D39: TungNT188 | F39: done | H39: Sprint 3 | M39: =IF($C39="","",IF($F39="done",0,MAX($E39-$L39,0))) -> 0
A40: US-15 | B40: T-151 | C40: Generate short-lived HMAC-signed URL | D40: TienPQ9 | F40: done | H40: Sprint 3 | M40: =IF($C40="","",IF($F40="done",0,MAX($E40-$L40,0))) -> 0
...

Sheet Sprint Summary
A1: Sprint summary - every number here is a formula over the WBS and Backlog sheets.
A2: Member view sprint: | C2: Sprint 2
A4: Sprint | B4: Stories | C4: Points | D4: Tasks | E4: Est (h) | F4: Actual (h) | G4: Remain (h) | H4: done | I4: in-progress | J4: todo | K4: pending | L4: % done (h)
A5: Sprint 1 | B5: =COUNTIF(Backlog!$H:$H,$A5) -> 1 | C5: =SUMIF(Backlog!$H:$H,$A5,Backlog!$G:$G) -> 8 | D5: =COUNTIF(WBS!$H:$H,$A5) -> 8 | E5: =SUMIF(WBS!$H:$H,$A5,WBS!$E:$E) -> 0 | F5: =SUMIF(WBS!$H:$H,$A5,WBS!$L:$L) -> 0 | G5: =SUMIF(WBS!$H:$H,$A5,WBS!$M:$M) -> 0 | H5: =COUNTIFS(WBS!$H:$H,$A5,WBS!$F:$F,"done") -> 8 | I5: =COUNTIFS(WBS!$H:$H,$A5,WBS!$F:$F,"in-progress") -> 0 | J5: =COUNTIFS(WBS!$H:$H,$A5,WBS!$F:$F,"todo") -> 0 | K5: =COUNTIFS(WBS!$H:$H,$A5,WBS!$F:$F,"pending") -> 0 | L5: =IFERROR(SUMIFS(WBS!$E:$E,WBS!$H:$H,$A5,WBS!$F:$F,"done")/$E5,0) -> 0
A6: Sprint 2 | B6: =COUNTIF(Backlog!$H:$H,$A6) -> 8 | C6: =SUMIF(Backlog!$H:$H,$A6,Backlog!$G:$G) -> 44 | D6: =COUNTIF(WBS!$H:$H,$A6) -> 22 | E6: =SUMIF(WBS!$H:$H,$A6,WBS!$E:$E) -> 0 | F6: =SUMIF(WBS!$H:$H,$A6,WBS!$L:$L) -> 0 | G6: =SUMIF(WBS!$H:$H,$A6,WBS!$M:$M) -> 0 | H6: =COUNTIFS(WBS!$H:$H,$A6,WBS!$F:$F,"done") -> 22 | I6: =COUNTIFS(WBS!$H:$H,$A6,WBS!$F:$F,"in-progress") -> 0 | J6: =COUNTIFS(WBS!$H:$H,$A6,WBS!$F:$F,"todo") -> 0 | K6: =COUNTIFS(WBS!$H:$H,$A6,WBS!$F:$F,"pending") -> 0 | L6: =IFERROR(SUMIFS(WBS!$E:$E,WBS!$H:$H,$A6,WBS!$F:$F,"done")/$E6,0) -> 0
A7: Sprint 3 | B7: =COUNTIF(Backlog!$H:$H,$A7) -> 7 | C7: =SUMIF(Backlog!$H:$H,$A7,Backlog!$G:$G) -> 60 | D7: =COUNTIF(WBS!$H:$H,$A7) -> 12 | E7: =SUMIF(WBS!$H:$H,$A7,WBS!$E:$E) -> 0 | F7: =SUMIF(WBS!$H:$H,$A7,WBS!$L:$L) -> 0 | G7: =SUMIF(WBS!$H:$H,$A7,WBS!$M:$M) -> 0 | H7: =COUNTIFS(WBS!$H:$H,$A7,WBS!$F:$F,"done") -> 12 | I7: =COUNTIFS(WBS!$H:$H,$A7,WBS!$F:$F,"in-progress") -> 0 | J7: =COUNTIFS(WBS!$H:$H,$A7,WBS!$F:$F,"todo") -> 0 | K7: =COUNTIFS(WBS!$H:$H,$A7,WBS!$F:$F,"pending") -> 0 | L7: =IFERROR(SUMIFS(WBS!$E:$E,WBS!$H:$H,$A7,WBS!$F:$F,"done")/$E7,0) -> 0
A8: Sprint 4 | B8: =COUNTIF(Backlog!$H:$H,$A8) -> 7 | C8: =SUMIF(Backlog!$H:$H,$A8,Backlog!$G:$G) -> 32 | D8: =COUNTIF(WBS!$H:$H,$A8) -> 12 | E8: =SUMIF(WBS!$H:$H,$A8,WBS!$E:$E) -> 0 | F8: =SUMIF(WBS!$H:$H,$A8,WBS!$L:$L) -> 0 | G8: =SUMIF(WBS!$H:$H,$A8,WBS!$M:$M) -> 0 | H8: =COUNTIFS(WBS!$H:$H,$A8,WBS!$F:$F,"done") -> 12 | I8: =COUNTIFS(WBS!$H:$H,$A8,WBS!$F:$F,"in-progress") -> 0 | J8: =COUNTIFS(WBS!$H:$H,$A8,WBS!$F:$F,"todo") -> 0 | K8: =COUNTIFS(WBS!$H:$H,$A8,WBS!$F:$F,"pending") -> 0 | L8: =IFERROR(SUMIFS(WBS!$E:$E,WBS!$H:$H,$A8,WBS!$F:$F,"done")/$E8,0) -> 0
A9: Backlog | B9: =COUNTIF(Backlog!$H:$H,$A9) -> 0 | C9: =SUMIF(Backlog!$H:$H,$A9,Backlog!$G:$G) -> 0 | D9: =COUNTIF(WBS!$H:$H,$A9) -> 0 | E9: =SUMIF(WBS!$H:$H,$A9,WBS!$E:$E) -> 0 | F9: =SUMIF(WBS!$H:$H,$A9,WBS!$L:$L) -> 0 | G9: =SUMIF(WBS!$H:$H,$A9,WBS!$M:$M) -> 0 | H9: =COUNTIFS(WBS!$H:$H,$A9,WBS!$F:$F,"done") -> 0 | I9: =COUNTIFS(WBS!$H:$H,$A9,WBS!$F:$F,"in-progress") -> 0 | J9: =COUNTIFS(WBS!$H:$H,$A9,WBS!$F:$F,"todo") -> 0 | K9: =COUNTIFS(WBS!$H:$H,$A9,WBS!$F:$F,"pending") -> 0 | L9: =IFERROR(SUMIFS(WBS!$E:$E,WBS!$H:$H,$A9,WBS!$F:$F,"done")/$E9,0) -> 0
A12: Per member - for the sprint picked in C2
A13: Member | B13: Tasks | C13: Est (h) | D13: Actual (h) | E13: Remain (h) | F13: done | G13: in-progress | H13: todo | I13: pending | J13: Capacity (h) | K13: Load
A14: =IF('Master Data'!$O$5="","",'Master Data'!$O$5) -> TienPQ9 | B14: =COUNTIFS(WBS!$D:$D,$A14,WBS!$H:$H,$C$2) -> 9 | C14: =SUMIFS(WBS!$E:$E,WBS!$D:$D,$A14,WBS!$H:$H,$C$2) -> 0 | D14: =SUMIFS(WBS!$L:$L,WBS!$D:$D,$A14,WBS!$H:$H,$C$2) -> 0 | E14: =SUMIFS(WBS!$M:$M,WBS!$D:$D,$A14,WBS!$H:$H,$C$2) -> 0 | F14: =COUNTIFS(WBS!$D:$D,$A14,WBS!$H:$H,$C$2,WBS!$F:$F,"done") -> 9 | G14: =COUNTIFS(WBS!$D:$D,$A14,WBS!$H:$H,$C$2,WBS!$F:$F,"in-progress") -> 0 | H14: =COUNTIFS(WBS!$D:$D,$A14,WBS!$H:$H,$C$2,WBS!$F:$F,"todo") -> 0 | I14: =COUNTIFS(WBS!$D:$D,$A14,WBS!$H:$H,$C$2,WBS!$F:$F,"pending") -> 0 | J14: 30 | K14: =IFERROR($C14/$J14,0) -> 0
A15: =IF('Master Data'!$O$6="","",'Master Data'!$O$6) -> DuongNT182 | B15: =COUNTIFS(WBS!$D:$D,$A15,WBS!$H:$H,$C$2) -> 4 | C15: =SUMIFS(WBS!$E:$E,WBS!$D:$D,$A15,WBS!$H:$H,$C$2) -> 0 | D15: =SUMIFS(WBS!$L:$L,WBS!$D:$D,$A15,WBS!$H:$H,$C$2) -> 0 | E15: =SUMIFS(WBS!$M:$M,WBS!$D:$D,$A15,WBS!$H:$H,$C$2) -> 0 | F15: =COUNTIFS(WBS!$D:$D,$A15,WBS!$H:$H,$C$2,WBS!$F:$F,"done") -> 4 | G15: =COUNTIFS(WBS!$D:$D,$A15,WBS!$H:$H,$C$2,WBS!$F:$F,"in-progress") -> 0 | H15: =COUNTIFS(WBS!$D:$D,$A15,WBS!$H:$H,$C$2,WBS!$F:$F,"todo") -> 0 | I15: =COUNTIFS(WBS!$D:$D,$A15,WBS!$H:$H,$C$2,WBS!$F:$F,"pending") -> 0 | J15: 30 | K15: =IFERROR($C15/$J15,0) -> 0
A16: =IF('Master Data'!$O$7="","",'Master Data'!$O$7) -> TungNT188 | B16: =COUNTIFS(WBS!$D:$D,$A16,WBS!$H:$H,$C$2) -> 9 | C16: =SUMIFS(WBS!$E:$E,WBS!$D:$D,$A16,WBS!$H:$H,$C$2) -> 0 | D16: =SUMIFS(WBS!$L:$L,WBS!$D:$D,$A16,WBS!$H:$H,$C$2) -> 0 | E16: =SUMIFS(WBS!$M:$M,WBS!$D:$D,$A16,WBS!$H:$H,$C$2) -> 0 | F16: =COUNTIFS(WBS!$D:$D,$A16,WBS!$H:$H,$C$2,WBS!$F:$F,"done") -> 9 | G16: =COUNTIFS(WBS!$D:$D,$A16,WBS!$H:$H,$C$2,WBS!$F:$F,"in-progress") -> 0 | H16: =COUNTIFS(WBS!$D:$D,$A16,WBS!$H:$H,$C$2,WBS!$F:$F,"todo") -> 0 | I16: =COUNTIFS(WBS!$D:$D,$A16,WBS!$H:$H,$C$2,WBS!$F:$F,"pending") -> 0 | J16: 30 | K16: =IFERROR($C16/$J16,0) -> 0
A17: =IF('Master Data'!$O$8="","",'Master Data'!$O$8) | B17: =COUNTIFS(WBS!$D:$D,$A17,WBS!$H:$H,$C$2) -> 0 | C17: =SUMIFS(WBS!$E:$E,WBS!$D:$D,$A17,WBS!$H:$H,$C$2) -> 0 | D17: =SUMIFS(WBS!$L:$L,WBS!$D:$D,$A17,WBS!$H:$H,$C$2) -> 0 | E17: =SUMIFS(WBS!$M:$M,WBS!$D:$D,$A17,WBS!$H:$H,$C$2) -> 0 | F17: =COUNTIFS(WBS!$D:$D,$A17,WBS!$H:$H,$C$2,WBS!$F:$F,"done") -> 0 | G17: =COUNTIFS(WBS!$D:$D,$A17,WBS!$H:$H,$C$2,WBS!$F:$F,"in-progress") -> 0 | H17: =COUNTIFS(WBS!$D:$D,$A17,WBS!$H:$H,$C$2,WBS!$F:$F,"todo") -> 0 | I17: =COUNTIFS(WBS!$D:$D,$A17,WBS!$H:$H,$C$2,WBS!$F:$F,"pending") -> 0 | J17: 30 | K17: =IFERROR($C17/$J17,0) -> 0
A18: =IF('Master Data'!$O$9="","",'Master Data'!$O$9) -> <acc5> | B18: =COUNTIFS(WBS!$D:$D,$A18,WBS!$H:$H,$C$2) -> 0 | C18: =SUMIFS(WBS!$E:$E,WBS!$D:$D,$A18,WBS!$H:$H,$C$2) -> 0 | D18: =SUMIFS(WBS!$L:$L,WBS!$D:$D,$A18,WBS!$H:$H,$C$2) -> 0 | E18: =SUMIFS(WBS!$M:$M,WBS!$D:$D,$A18,WBS!$H:$H,$C$2) -> 0 | F18: =COUNTIFS(WBS!$D:$D,$A18,WBS!$H:$H,$C$2,WBS!$F:$F,"done") -> 0 | G18: =COUNTIFS(WBS!$D:$D,$A18,WBS!$H:$H,$C$2,WBS!$F:$F,"in-progress") -> 0 | H18: =COUNTIFS(WBS!$D:$D,$A18,WBS!$H:$H,$C$2,WBS!$F:$F,"todo") -> 0 | I18: =COUNTIFS(WBS!$D:$D,$A18,WBS!$H:$H,$C$2,WBS!$F:$F,"pending") -> 0 | J18: 30 | K18: =IFERROR($C18/$J18,0) -> 0
A20: Capacity (h) is the only cell you type here: the hours that member really has in the sprint. Load over 100% means the sprint is over-committed - move a task out before the sprint starts, not on the last day.

Sheet Master Data
A1: Master data - the allowed values behind every dropdown in this workbook.
A2: Status, Priority, Points, Risk and Type are fixed by the brief - do not rename them. Assignee and Sprint are yours: put in your team and check the dates against submission_guide.md.
A4: Status | B4: When to use it | C4: Note required? | E4: Priority | F4: Meaning (MoSCoW) | H4: Points | J4: Sprint | K4: Start | L4: End | M4: Deadline | O4: Assignee | P4: Full name | Q4: Role in the team | S4: Task Type | U4: Story Type | W4: Risk | X4: Meaning | Z4: Yes/No | AB4: ID format | AC4: Example | AD4: Rule
A5: todo | B5: Planned, nobody has started it yet. | C5: Only when it is waiting on something, or was added after the freeze. | E5: Must | F5: Ship it or the product does not work. | H5: 1 | J5: Sprint 1 | K5: 46247 | L5: 46253 | M5: 2026-08-19 23:59 | O5: TienPQ9 | P5: Phung Quang Tien | Q5: Frontend / Backend | S5: Analysis | U5: Feature | W5: Low | X5: Known ground, no unknowns left. | Z5: Yes | AB5: Story ID | AC5: US-01 | AD5: US- plus two digits. One row per story on the Backlog sheet.
A6: in-progress | B6: Someone is working on it right now. | C6: Yes - name the concrete step you are on. | E6: Should | F6: Important, but the sprint survives without it. | H6: 2 | J6: Sprint 2 | K6: 46254 | L6: 46259 | M6: 2026-08-25 23:59 | O6: DuongNT182 | P6: Nguyễn Tùng Dương | Q6: Frontend / Backend | S6: Design | U6: Tech | W6: Medium | X6: One unknown - a library or an API nobody used yet. | Z6: No | AB6: Task ID | AC6: T-011 | AD6: T- plus story number plus a task number: T-011 is task 1 of US-01.
A7: done | B7: Merged into the default branch and it works. | C7: Optional - evidence, or the scope you cut. | E7: Could | F7: Nice to have if there is time left. | H7: 3 | J7: Sprint 3 | K7: 46260 | L7: 46269 | M7: 2026-09-04 23:59 | O7: TungNT188 | P7: Nguyễn Thanh Tùng | Q7: Frontend / Backend | S7: Database | U7: Bug | W7: High | X7: Technical hard core, or a third-party the team cannot control. | AB7: Account | AC7: AlexDF | AD7: First name plus the initials of the remaining parts: Alex De Fleu.
A8: pending | B8: Started or planned, then stopped. | C8: Yes - why it stopped and what unblocks it. | E8: Won't | F8: Agreed out of scope for this release. | H8: 5 | J8: Sprint 4 | K8: 46272 | L8: 46276 | M8: 2026-09-11 23:59 | S8: Backend | U8: Spike
H9: 8 | J9: Backlog | M9: Not scheduled yet | O9: <acc5> | P9: <full name> | Q9: <role> | S9: Frontend | U9: Chore
H10: 13 | S10: Integration
S11: Test
S12: Docs
S13: DevOps
S14: Spike
S15: Bugfix

Sheet Guide
A1: What is in this workbook
A2: Backlog | B2: One row per user story - the story, its acceptance criteria, priority, size, owner, risk and the sprint that owns it. Tasks / Est / Actual / Remain / Progress are formulas rolled up from WBS on Story ID.
A3: WBS | B3: One row per task. A-G are the task itself - story, id, name, owner, estimate, status, note; H-Q are the planning, review and evidence columns D02 asks for: the plan, the actual result, and who contributed what.
A4: Sprint Summary | B4: Read-only roll-up: per sprint and per member. Pick the sprint in cell C2, type each member's real Capacity (h), and the Load column tells you who is over-committed.
A5: Master Data | B5: Every dropdown reads from here, plus the ID formats. Replace the Assignee list with your team; leave Status, Priority, Points, Risk and Type alone.
A7: IDs
A8: Story ID | B8: US- plus two digits (US-01). Lives on the Backlog sheet; the WBS Story ID column is a dropdown of those IDs.
A9: Task ID | B9: T- plus the story number plus a task number: T-011 is task 1 of US-01, T-023 is task 3 of US-02. Unique across the project - the sprint review record and your commit messages refer to it.
A10: Task | B10: Just the name, no ID in it: 'Double-booking check API'.
A11: Account | B11: First name plus the initials of the remaining parts - Alex De Fleu becomes AlexDF.
A13: Filling it in
A14: Blue text | B14: A formula. Typing over one breaks the roll-up - everything else on Backlog and WBS is yours to fill in.
A15: Yellow cells | B15: Only on Sprint Summary: Capacity (h), the one thing you type on that sheet.
A16: Example rows | B16: Backlog rows 2-5 and WBS rows 2-15 are worked examples. Delete every one before you submit.
A17: Story <-> task link | B17: The roll-up matches WBS Story ID against Backlog Story ID exactly. Use the dropdown; a hand-typed 'US-1' silently shows 0 tasks.
A18: One owner per task | B18: Assignee takes exactly one name. A task nobody owns counts as missing at gate G1.
A19: Remain (h) | B19: A formula: 0 once the task is done, otherwise Estimate minus Actual. Sum it per sprint for your burndown.
A21: Status - the only four values
A22: todo | B22: Planned, not started.
A23: in-progress | B23: Being worked on right now.
A24: done | B24: Merged into the default branch and working.
A25: pending | B25: Started or planned, then stopped. Not the same as todo - somebody is waiting on something.
A27: What goes in the Note column
A28: todo | B28: Usually empty. Write a note only when it is waiting on something: 'Not started - starts when T-012 is merged'.
A29: in-progress | B29: Always. Name the concrete step, not the status: 'Slot query done; writing the overlap check in AppointmentService'. 'Implementing' says nothing.
A30: done | B30: Empty when it shipped as planned. Add evidence ('Merged in PR #34 with 6 unit tests') or the scope you cut ('Reduced scope - email only; SMS moved to T-034').
A31: pending | B31: Always. Why it stopped, since when, and what unblocks it: 'Blocked - no sandbox credentials from the SMS provider yet'. For carry-over, add the hours spent and the branch.
A32: Added <YYYY-MM-DD> | B32: Required by gate G1 on any task added after the freeze. It goes first in the Note, then the description - and the same change must appear in sprint<N>_review.md as a scope change.
A34: Submitting for gate G1
A35: 1 | B35: Freeze the backlog before the sprint starts: every task planned, owned and estimated.
A36: 2 | B36: Anything added after the freeze carries Added <YYYY-MM-DD> first in its Note, and shows up in sprint<N>_review.md as a scope change.
A37: 3 | B37: At the end of the sprint, File > Save a Copy as backlog_sprint<N>.xlsx. One file per sprint - there is no open/close pair.
A38: 4 | B38: Upload it to <CLASS>/<TEAM>/Sprint <N>/ on Drive and leave it alone: that copy is the frozen record. The Drive upload time is the submission time - see submission_guide.md.
